2022-01-12 18:20:48.280 Trying to detect encoding from a tiny portion of (15) byte(s).
2022-01-12 18:20:48.282 ascii passed initial chaos probing. Mean measured chaos is 0.000000 %
2022-01-12 18:20:48.282 ascii should target any language(s) of ['Latin Based']
2022-01-12 18:20:48.282 ascii is most likely the one. Stopping the process.

  You can now view your Streamlit app in your browser.

  Network URL: http://10.21.0.126:8503
  External URL: http://177.190.215.14:8503

2022-01-12 19:32:33.686 Traceback (most recent call last):
  File "/dados01/workspace/ufmg.f01dcc2021/env-dash/lib/python3.8/site-packages/streamlit/script_runner.py", line 354, in _run_script
    exec(code, module.__dict__)
  File "/dados01/workspace/ufmg.f01dcc2021/dev/issue-generator/src/app.py", line 70, in <module>
    main(template_issue)
  File "/dados01/workspace/ufmg.f01dcc2021/dev/issue-generator/src/app.py", line 63, in main
    repo = g.get_repo("CinthiaS/test")
  File "/dados01/workspace/ufmg.f01dcc2021/env-dash/lib/python3.8/site-packages/github/MainClass.py", line 330, in get_repo
    headers, data = self.__requester.requestJsonAndCheck("GET", url)
  File "/dados01/workspace/ufmg.f01dcc2021/env-dash/lib/python3.8/site-packages/github/Requester.py", line 353, in requestJsonAndCheck
    return self.__check(
  File "/dados01/workspace/ufmg.f01dcc2021/env-dash/lib/python3.8/site-packages/github/Requester.py", line 378, in __check
    raise self.__createException(status, responseHeaders, output)
github.GithubException.BadCredentialsException: 401 {"message": "Bad credentials", "documentation_url": "https://docs.github.com/rest"}

2022-01-12 19:39:08.999 Traceback (most recent call last):
  File "/dados01/workspace/ufmg.f01dcc2021/env-dash/lib/python3.8/site-packages/streamlit/script_runner.py", line 354, in _run_script
    exec(code, module.__dict__)
  File "/dados01/workspace/ufmg.f01dcc2021/dev/issue-generator/src/app.py", line 67, in <module>
    main(template_issue)
  File "/dados01/workspace/ufmg.f01dcc2021/dev/issue-generator/src/app.py", line 60, in main
    repo = g.get_repo("/CinthiaS/test")
  File "/dados01/workspace/ufmg.f01dcc2021/env-dash/lib/python3.8/site-packages/github/MainClass.py", line 330, in get_repo
    headers, data = self.__requester.requestJsonAndCheck("GET", url)
  File "/dados01/workspace/ufmg.f01dcc2021/env-dash/lib/python3.8/site-packages/github/Requester.py", line 353, in requestJsonAndCheck
    return self.__check(
  File "/dados01/workspace/ufmg.f01dcc2021/env-dash/lib/python3.8/site-packages/github/Requester.py", line 378, in __check
    raise self.__createException(status, responseHeaders, output)
github.GithubException.UnknownObjectException: 404 {"message": "Not Found", "documentation_url": "https://docs.github.com/rest"}

2022-01-12 20:00:59.131 Traceback (most recent call last):
  File "/dados01/workspace/ufmg.f01dcc2021/env-dash/lib/python3.8/site-packages/streamlit/script_runner.py", line 354, in _run_script
    exec(code, module.__dict__)
  File "/dados01/workspace/ufmg.f01dcc2021/dev/issue-generator/src/app.py", line 64, in <module>
    main(template_issue)
  File "/dados01/workspace/ufmg.f01dcc2021/dev/issue-generator/src/app.py", line 57, in main
    repo = login(token=git_token)
NameError: name 'login' is not defined

2022-01-12 20:24:07.671 Traceback (most recent call last):
  File "/dados01/workspace/ufmg.f01dcc2021/env-dash/lib/python3.8/site-packages/streamlit/script_runner.py", line 354, in _run_script
    exec(code, module.__dict__)
  File "/dados01/workspace/ufmg.f01dcc2021/dev/issue-generator/src/app.py", line 64, in <module>
    main(template_issue)
  File "/dados01/workspace/ufmg.f01dcc2021/dev/issue-generator/src/app.py", line 60, in main
    create_all_issues(issues, user, git_token)
  File "/dados01/workspace/ufmg.f01dcc2021/dev/issue-generator/src/app.py", line 33, in create_all_issues
    if st.button('Criar Issue'):
  File "/dados01/workspace/ufmg.f01dcc2021/env-dash/lib/python3.8/site-packages/streamlit/elements/button.py", line 91, in button
    return self.dg._button(
  File "/dados01/workspace/ufmg.f01dcc2021/env-dash/lib/python3.8/site-packages/streamlit/elements/button.py", line 274, in _button
    current_value, _ = register_widget(
  File "/dados01/workspace/ufmg.f01dcc2021/env-dash/lib/python3.8/site-packages/streamlit/state/widgets.py", line 148, in register_widget
    raise DuplicateWidgetID(
streamlit.errors.DuplicateWidgetID: There are multiple identical `st.button` widgets with the
same generated key.

When a widget is created, it's assigned an internal key based on
its structure. Multiple widgets with an identical structure will
result in the same internal key, which causes this error.

To fix this error, please pass a unique `key` argument to
`st.button`.

2022-01-12 20:29:27.709 Traceback (most recent call last):
  File "/dados01/workspace/ufmg.f01dcc2021/env-dash/lib/python3.8/site-packages/streamlit/script_runner.py", line 354, in _run_script
    exec(code, module.__dict__)
  File "/dados01/workspace/ufmg.f01dcc2021/dev/issue-generator/src/app.py", line 74, in <module>
    main(template_issue)
  File "/dados01/workspace/ufmg.f01dcc2021/dev/issue-generator/src/app.py", line 70, in main
    create_all_issues(issues, user, git_token)
  File "/dados01/workspace/ufmg.f01dcc2021/dev/issue-generator/src/app.py", line 37, in create_all_issues
    if st.button('Criar Issue'):
  File "/dados01/workspace/ufmg.f01dcc2021/env-dash/lib/python3.8/site-packages/streamlit/elements/button.py", line 91, in button
    return self.dg._button(
  File "/dados01/workspace/ufmg.f01dcc2021/env-dash/lib/python3.8/site-packages/streamlit/elements/button.py", line 274, in _button
    current_value, _ = register_widget(
  File "/dados01/workspace/ufmg.f01dcc2021/env-dash/lib/python3.8/site-packages/streamlit/state/widgets.py", line 148, in register_widget
    raise DuplicateWidgetID(
streamlit.errors.DuplicateWidgetID: There are multiple identical `st.button` widgets with the
same generated key.

When a widget is created, it's assigned an internal key based on
its structure. Multiple widgets with an identical structure will
result in the same internal key, which causes this error.

To fix this error, please pass a unique `key` argument to
`st.button`.

2022-01-12 20:30:23.126 Traceback (most recent call last):
  File "/dados01/workspace/ufmg.f01dcc2021/env-dash/lib/python3.8/site-packages/streamlit/script_runner.py", line 354, in _run_script
    exec(code, module.__dict__)
  File "/dados01/workspace/ufmg.f01dcc2021/dev/issue-generator/src/app.py", line 74, in <module>
    main(template_issue)
  File "/dados01/workspace/ufmg.f01dcc2021/dev/issue-generator/src/app.py", line 70, in main
    create_all_issues(issues, user, git_token)
  File "/dados01/workspace/ufmg.f01dcc2021/dev/issue-generator/src/app.py", line 37, in create_all_issues
    if st.button('Criar Issue', key=0):
  File "/dados01/workspace/ufmg.f01dcc2021/env-dash/lib/python3.8/site-packages/streamlit/elements/button.py", line 91, in button
    return self.dg._button(
  File "/dados01/workspace/ufmg.f01dcc2021/env-dash/lib/python3.8/site-packages/streamlit/elements/button.py", line 274, in _button
    current_value, _ = register_widget(
  File "/dados01/workspace/ufmg.f01dcc2021/env-dash/lib/python3.8/site-packages/streamlit/state/widgets.py", line 148, in register_widget
    raise DuplicateWidgetID(
streamlit.errors.DuplicateWidgetID: There are multiple identical `st.button` widgets with
`key='0'`.

To fix this, please make sure that the `key` argument is unique for
each `st.button` you create.

2022-01-12 20:31:11.631 Traceback (most recent call last):
  File "/dados01/workspace/ufmg.f01dcc2021/env-dash/lib/python3.8/site-packages/streamlit/script_runner.py", line 354, in _run_script
    exec(code, module.__dict__)
  File "/dados01/workspace/ufmg.f01dcc2021/dev/issue-generator/src/app.py", line 74, in <module>
    main(template_issue)
  File "/dados01/workspace/ufmg.f01dcc2021/dev/issue-generator/src/app.py", line 70, in main
    create_all_issues(issues, user, git_token)
  File "/dados01/workspace/ufmg.f01dcc2021/dev/issue-generator/src/app.py", line 37, in create_all_issues
    if st.button('Criar Issue', key=1):
  File "/dados01/workspace/ufmg.f01dcc2021/env-dash/lib/python3.8/site-packages/streamlit/elements/button.py", line 91, in button
    return self.dg._button(
  File "/dados01/workspace/ufmg.f01dcc2021/env-dash/lib/python3.8/site-packages/streamlit/elements/button.py", line 274, in _button
    current_value, _ = register_widget(
  File "/dados01/workspace/ufmg.f01dcc2021/env-dash/lib/python3.8/site-packages/streamlit/state/widgets.py", line 148, in register_widget
    raise DuplicateWidgetID(
streamlit.errors.DuplicateWidgetID: There are multiple identical `st.button` widgets with
`key='1'`.

To fix this, please make sure that the `key` argument is unique for
each `st.button` you create.

2022-01-12 20:32:42.190 Traceback (most recent call last):
  File "/dados01/workspace/ufmg.f01dcc2021/env-dash/lib/python3.8/site-packages/streamlit/script_runner.py", line 354, in _run_script
    exec(code, module.__dict__)
  File "/dados01/workspace/ufmg.f01dcc2021/dev/issue-generator/src/app.py", line 76, in <module>
    main(template_issue)
  File "/dados01/workspace/ufmg.f01dcc2021/dev/issue-generator/src/app.py", line 72, in main
    create_all_issues(issues, user, git_token)
  File "/dados01/workspace/ufmg.f01dcc2021/dev/issue-generator/src/app.py", line 37, in create_all_issues
    if st.button('Criar Issue', key=1):
  File "/dados01/workspace/ufmg.f01dcc2021/env-dash/lib/python3.8/site-packages/streamlit/elements/button.py", line 91, in button
    return self.dg._button(
  File "/dados01/workspace/ufmg.f01dcc2021/env-dash/lib/python3.8/site-packages/streamlit/elements/button.py", line 274, in _button
    current_value, _ = register_widget(
  File "/dados01/workspace/ufmg.f01dcc2021/env-dash/lib/python3.8/site-packages/streamlit/state/widgets.py", line 148, in register_widget
    raise DuplicateWidgetID(
streamlit.errors.DuplicateWidgetID: There are multiple identical `st.button` widgets with
`key='1'`.

To fix this, please make sure that the `key` argument is unique for
each `st.button` you create.

2022-01-14 08:13:17.472 Trying to detect encoding from a tiny portion of (15) byte(s).
2022-01-14 08:13:17.480 ascii passed initial chaos probing. Mean measured chaos is 0.000000 %
2022-01-14 08:13:17.481 ascii should target any language(s) of ['Latin Based']
2022-01-14 08:13:17.481 ascii is most likely the one. Stopping the process.

  You can now view your Streamlit app in your browser.

  Network URL: http://10.21.0.126:8503
  External URL: http://177.190.215.14:8503

  Stopping...
2022-01-14 08:15:33.663 Trying to detect encoding from a tiny portion of (15) byte(s).
2022-01-14 08:15:33.665 ascii passed initial chaos probing. Mean measured chaos is 0.000000 %
2022-01-14 08:15:33.665 ascii should target any language(s) of ['Latin Based']
2022-01-14 08:15:33.666 ascii is most likely the one. Stopping the process.

  You can now view your Streamlit app in your browser.

  Network URL: http://10.21.0.126:8060
  External URL: http://177.190.215.14:8060

[I 08:17:35.448 NotebookApp] Serving notebooks from local directory: /dados01/workspace/ufmg.f01dcc2021/dev/issue-generator
[I 08:17:35.448 NotebookApp] Jupyter Notebook 6.4.6 is running at:
[I 08:17:35.448 NotebookApp] http://localhost:8070/?token=e29c2f0780c640ab3c3e22e80138e7f4380c5ee97f567060
[I 08:17:35.448 NotebookApp]  or http://127.0.0.1:8070/?token=e29c2f0780c640ab3c3e22e80138e7f4380c5ee97f567060
[I 08:17:35.448 NotebookApp] Use Control-C to stop this server and shut down all kernels (twice to skip confirmation).
[C 08:17:35.453 NotebookApp] 
    
    To access the notebook, open this file in a browser:
        file:///dados01/workspace/ufmg.f01dcc2021/.local/share/jupyter/runtime/nbserver-108264-open.html
    Or copy and paste one of these URLs:
        http://localhost:8070/?token=e29c2f0780c640ab3c3e22e80138e7f4380c5ee97f567060
     or http://127.0.0.1:8070/?token=e29c2f0780c640ab3c3e22e80138e7f4380c5ee97f567060
[I 09:07:18.368 NotebookApp] 302 GET / (::1) 1.100000ms
[I 09:07:18.589 NotebookApp] 302 GET /tree? (::1) 1.650000ms
[I 09:08:04.802 NotebookApp] 302 POST /login?next=%2Ftree%3F (::1) 1.640000ms
2022-01-15 17:33:34.543 Traceback (most recent call last):
  File "/dados01/workspace/ufmg.f01dcc2021/env-dash/lib/python3.8/site-packages/streamlit/script_runner.py", line 354, in _run_script
    exec(code, module.__dict__)
  File "/dados01/workspace/ufmg.f01dcc2021/dev/issue-generator/src/app.py", line 89, in <module>
    main(template_issue)
  File "/dados01/workspace/ufmg.f01dcc2021/dev/issue-generator/src/app.py", line 77, in main
    i = repo.create_issue(
  File "/dados01/workspace/ufmg.f01dcc2021/env-dash/lib/python3.8/site-packages/github/Repository.py", line 1218, in create_issue
    headers, data = self._requester.requestJsonAndCheck(
  File "/dados01/workspace/ufmg.f01dcc2021/env-dash/lib/python3.8/site-packages/github/Requester.py", line 353, in requestJsonAndCheck
    return self.__check(
  File "/dados01/workspace/ufmg.f01dcc2021/env-dash/lib/python3.8/site-packages/github/Requester.py", line 378, in __check
    raise self.__createException(status, responseHeaders, output)
github.GithubException.GithubException: 403 {"message": "You have exceeded a secondary rate limit and have been temporarily blocked from content creation. Please retry your request again later.", "documentation_url": "https://docs.github.com/rest/overview/resources-in-the-rest-api#secondary-rate-limits"}

/dados01/workspace/ufmg_2021_f01/ufmg.cmikaela/.local/lib/python3.6/site-packages/streamlit/bootstrap.py:110: UserWarning: 
This call to matplotlib.use() has no effect because the backend has already
been chosen; matplotlib.use() must be called *before* pylab, matplotlib.pyplot,
or matplotlib.backends is imported for the first time.

The backend was *originally* set to 'TkAgg' by the following code:
  File "/dados01/workspace/ufmg_2021_f01/ufmg.cmikaela/.local/bin/streamlit", line 5, in <module>
    from streamlit.cli import main
  File "/dados01/workspace/ufmg_2021_f01/ufmg.cmikaela/.local/lib/python3.6/site-packages/streamlit/__init__.py", line 72, in <module>
    from streamlit.delta_generator import DeltaGenerator as _DeltaGenerator
  File "/dados01/workspace/ufmg_2021_f01/ufmg.cmikaela/.local/lib/python3.6/site-packages/streamlit/delta_generator.py", line 71, in <module>
    from streamlit.elements.arrow import ArrowMixin
  File "/dados01/workspace/ufmg_2021_f01/ufmg.cmikaela/.local/lib/python3.6/site-packages/streamlit/elements/arrow.py", line 20, in <module>
    from pandas.io.formats.style import Styler
  File "/dados01/workspace/ufmg_2021_f01/ufmg.cmikaela/.local/lib/python3.6/site-packages/pandas/io/formats/style.py", line 46, in <module>
    import matplotlib.pyplot as plt
  File "/usr/local/lib64/python3.6/site-packages/matplotlib/pyplot.py", line 71, in <module>
    from matplotlib.backends import pylab_setup
  File "/usr/local/lib64/python3.6/site-packages/matplotlib/backends/__init__.py", line 17, in <module>
    line for line in traceback.format_stack()


  matplotlib.use("Agg")
2022-01-20 13:18:09.441 Traceback (most recent call last):
  File "/dados01/workspace/ufmg_2021_f01/ufmg.cmikaela/.local/lib/python3.6/site-packages/streamlit/script_runner.py", line 379, in _run_script
    exec(code, module.__dict__)
  File "/dados01/workspace/ufmg_2021_f01/ufmg.cmikaela/dev/issue-generator/src/app.py", line 2, in <module>
    from github3 import login
ModuleNotFoundError: No module named 'github3'


  You can now view your Streamlit app in your browser.

  Network URL: http://10.21.0.126:8060
  External URL: http://177.190.215.14:8060

2022-01-25 10:38:32.728 Traceback (most recent call last):
  File "/dados01/workspace/ufmg_2021_f01/ufmg.cmikaela/.local/lib/python3.6/site-packages/streamlit/script_runner.py", line 379, in _run_script
    exec(code, module.__dict__)
  File "/dados01/workspace/ufmg_2021_f01/ufmg.cmikaela/dev/issue-generator/src/app.py", line 89, in <module>
    main(template_issue)
  File "/dados01/workspace/ufmg_2021_f01/ufmg.cmikaela/dev/issue-generator/src/app.py", line 82, in main
    repo.get_label("Realização F01"), repo.get_label("Coleta")
  File "/dados01/workspace/ufmg_2021_f01/ufmg.cmikaela/.local/lib/python3.6/site-packages/github/Repository.py", line 1219, in create_issue
    "POST", f"{self.url}/issues", input=post_parameters
  File "/dados01/workspace/ufmg_2021_f01/ufmg.cmikaela/.local/lib/python3.6/site-packages/github/Requester.py", line 355, in requestJsonAndCheck
    verb, url, parameters, headers, input, self.__customConnection(url)
  File "/dados01/workspace/ufmg_2021_f01/ufmg.cmikaela/.local/lib/python3.6/site-packages/github/Requester.py", line 378, in __check
    raise self.__createException(status, responseHeaders, output)
github.GithubException.GithubException: 403 {"message": "You have exceeded a secondary rate limit and have been temporarily blocked from content creation. Please retry your request again later.", "documentation_url": "https://docs.github.com/rest/overview/resources-in-the-rest-api#secondary-rate-limits"}

2022-01-27 11:31:03.775 Traceback (most recent call last):
  File "/dados01/workspace/ufmg_2021_f01/ufmg.cmikaela/.local/lib/python3.6/site-packages/streamlit/script_runner.py", line 379, in _run_script
    exec(code, module.__dict__)
  File "/dados01/workspace/ufmg_2021_f01/ufmg.cmikaela/dev/issue-generator/src/app.py", line 89, in <module>
    main(template_issue)
  File "/dados01/workspace/ufmg_2021_f01/ufmg.cmikaela/dev/issue-generator/src/app.py", line 47, in main
    data = json.load(uploaded_file)
  File "/usr/lib64/python3.6/json/__init__.py", line 299, in load
    parse_constant=parse_constant, object_pairs_hook=object_pairs_hook, **kw)
  File "/usr/lib64/python3.6/json/__init__.py", line 354, in loads
    return _default_decoder.decode(s)
  File "/usr/lib64/python3.6/json/decoder.py", line 339, in decode
    obj, end = self.raw_decode(s, idx=_w(s, 0).end())
  File "/usr/lib64/python3.6/json/decoder.py", line 355, in raw_decode
    obj, end = self.scan_once(s, idx)
json.decoder.JSONDecodeError: Expecting property name enclosed in double quotes: line 22 column 1 (char 2092)

2022-01-27 11:31:50.496 Traceback (most recent call last):
  File "/dados01/workspace/ufmg_2021_f01/ufmg.cmikaela/.local/lib/python3.6/site-packages/streamlit/script_runner.py", line 379, in _run_script
    exec(code, module.__dict__)
  File "/dados01/workspace/ufmg_2021_f01/ufmg.cmikaela/dev/issue-generator/src/app.py", line 89, in <module>
    main(template_issue)
  File "/dados01/workspace/ufmg_2021_f01/ufmg.cmikaela/dev/issue-generator/src/app.py", line 72, in main
    repo = g.get_repo(repo_name)
  File "/dados01/workspace/ufmg_2021_f01/ufmg.cmikaela/.local/lib/python3.6/site-packages/github/MainClass.py", line 330, in get_repo
    headers, data = self.__requester.requestJsonAndCheck("GET", url)
  File "/dados01/workspace/ufmg_2021_f01/ufmg.cmikaela/.local/lib/python3.6/site-packages/github/Requester.py", line 355, in requestJsonAndCheck
    verb, url, parameters, headers, input, self.__customConnection(url)
  File "/dados01/workspace/ufmg_2021_f01/ufmg.cmikaela/.local/lib/python3.6/site-packages/github/Requester.py", line 378, in __check
    raise self.__createException(status, responseHeaders, output)
github.GithubException.UnknownObjectException: 404 {"message": "Not Found", "documentation_url": "https://docs.github.com/rest"}

2022-01-27 11:34:44.367 Traceback (most recent call last):
  File "/dados01/workspace/ufmg_2021_f01/ufmg.cmikaela/.local/lib/python3.6/site-packages/streamlit/script_runner.py", line 379, in _run_script
    exec(code, module.__dict__)
  File "/dados01/workspace/ufmg_2021_f01/ufmg.cmikaela/dev/issue-generator/src/app.py", line 89, in <module>
    main(template_issue)
  File "/dados01/workspace/ufmg_2021_f01/ufmg.cmikaela/dev/issue-generator/src/app.py", line 72, in main
    repo = g.get_repo(repo_name)
  File "/dados01/workspace/ufmg_2021_f01/ufmg.cmikaela/.local/lib/python3.6/site-packages/github/MainClass.py", line 330, in get_repo
    headers, data = self.__requester.requestJsonAndCheck("GET", url)
  File "/dados01/workspace/ufmg_2021_f01/ufmg.cmikaela/.local/lib/python3.6/site-packages/github/Requester.py", line 355, in requestJsonAndCheck
    verb, url, parameters, headers, input, self.__customConnection(url)
  File "/dados01/workspace/ufmg_2021_f01/ufmg.cmikaela/.local/lib/python3.6/site-packages/github/Requester.py", line 378, in __check
    raise self.__createException(status, responseHeaders, output)
github.GithubException.UnknownObjectException: 404 {"message": "Not Found", "documentation_url": "https://docs.github.com/rest"}

2022-01-27 11:35:17.077 Traceback (most recent call last):
  File "/dados01/workspace/ufmg_2021_f01/ufmg.cmikaela/.local/lib/python3.6/site-packages/streamlit/script_runner.py", line 379, in _run_script
    exec(code, module.__dict__)
  File "/dados01/workspace/ufmg_2021_f01/ufmg.cmikaela/dev/issue-generator/src/app.py", line 89, in <module>
    main(template_issue)
  File "/dados01/workspace/ufmg_2021_f01/ufmg.cmikaela/dev/issue-generator/src/app.py", line 72, in main
    repo = g.get_repo(repo_name)
  File "/dados01/workspace/ufmg_2021_f01/ufmg.cmikaela/.local/lib/python3.6/site-packages/github/MainClass.py", line 330, in get_repo
    headers, data = self.__requester.requestJsonAndCheck("GET", url)
  File "/dados01/workspace/ufmg_2021_f01/ufmg.cmikaela/.local/lib/python3.6/site-packages/github/Requester.py", line 355, in requestJsonAndCheck
    verb, url, parameters, headers, input, self.__customConnection(url)
  File "/dados01/workspace/ufmg_2021_f01/ufmg.cmikaela/.local/lib/python3.6/site-packages/github/Requester.py", line 378, in __check
    raise self.__createException(status, responseHeaders, output)
github.GithubException.UnknownObjectException: 404 {"message": "Not Found", "documentation_url": "https://docs.github.com/rest"}

2022-01-27 11:36:51.296 Traceback (most recent call last):
  File "/dados01/workspace/ufmg_2021_f01/ufmg.cmikaela/.local/lib/python3.6/site-packages/streamlit/script_runner.py", line 379, in _run_script
    exec(code, module.__dict__)
  File "/dados01/workspace/ufmg_2021_f01/ufmg.cmikaela/dev/issue-generator/src/app.py", line 89, in <module>
    main(template_issue)
  File "/dados01/workspace/ufmg_2021_f01/ufmg.cmikaela/dev/issue-generator/src/app.py", line 72, in main
    repo = g.get_repo(repo_name)
  File "/dados01/workspace/ufmg_2021_f01/ufmg.cmikaela/.local/lib/python3.6/site-packages/github/MainClass.py", line 330, in get_repo
    headers, data = self.__requester.requestJsonAndCheck("GET", url)
  File "/dados01/workspace/ufmg_2021_f01/ufmg.cmikaela/.local/lib/python3.6/site-packages/github/Requester.py", line 355, in requestJsonAndCheck
    verb, url, parameters, headers, input, self.__customConnection(url)
  File "/dados01/workspace/ufmg_2021_f01/ufmg.cmikaela/.local/lib/python3.6/site-packages/github/Requester.py", line 378, in __check
    raise self.__createException(status, responseHeaders, output)
github.GithubException.UnknownObjectException: 404 {"message": "Not Found", "documentation_url": "https://docs.github.com/rest"}

2022-01-30 10:28:50.391 Traceback (most recent call last):
  File "/dados01/workspace/ufmg_2021_f01/ufmg.cmikaela/.local/lib/python3.6/site-packages/streamlit/script_runner.py", line 379, in _run_script
    exec(code, module.__dict__)
  File "/dados01/workspace/ufmg_2021_f01/ufmg.cmikaela/dev/issue-generator/src/app.py", line 89, in <module>
    main(template_issue)
  File "/dados01/workspace/ufmg_2021_f01/ufmg.cmikaela/dev/issue-generator/src/app.py", line 82, in main
    repo.get_label("Realização F01"), repo.get_label("Coleta")
  File "/dados01/workspace/ufmg_2021_f01/ufmg.cmikaela/.local/lib/python3.6/site-packages/github/Repository.py", line 1219, in create_issue
    "POST", f"{self.url}/issues", input=post_parameters
  File "/dados01/workspace/ufmg_2021_f01/ufmg.cmikaela/.local/lib/python3.6/site-packages/github/Requester.py", line 355, in requestJsonAndCheck
    verb, url, parameters, headers, input, self.__customConnection(url)
  File "/dados01/workspace/ufmg_2021_f01/ufmg.cmikaela/.local/lib/python3.6/site-packages/github/Requester.py", line 378, in __check
    raise self.__createException(status, responseHeaders, output)
github.GithubException.GithubException: 403 {"message": "You have exceeded a secondary rate limit and have been temporarily blocked from content creation. Please retry your request again later.", "documentation_url": "https://docs.github.com/rest/overview/resources-in-the-rest-api#secondary-rate-limits"}

2022-02-03 12:37:51.506 Traceback (most recent call last):
  File "/dados01/workspace/ufmg_2021_f01/ufmg.cmikaela/.local/lib/python3.6/site-packages/streamlit/script_runner.py", line 379, in _run_script
    exec(code, module.__dict__)
  File "/dados01/workspace/ufmg_2021_f01/ufmg.cmikaela/dev/issue-generator/src/app.py", line 110, in <module>
    main(template_issue)
NameError: name 'template_issue' is not defined

2022-02-03 12:38:41.983 Traceback (most recent call last):
  File "/dados01/workspace/ufmg_2021_f01/ufmg.cmikaela/.local/lib/python3.6/site-packages/streamlit/script_runner.py", line 379, in _run_script
    exec(code, module.__dict__)
  File "/dados01/workspace/ufmg_2021_f01/ufmg.cmikaela/dev/issue-generator/src/app.py", line 110, in <module>
    main(template_issue_coleta, template_issue_generalizacao)
  File "/dados01/workspace/ufmg_2021_f01/ufmg.cmikaela/dev/issue-generator/src/app.py", line 78, in main
    for title, body in issues.items():
UnboundLocalError: local variable 'issues' referenced before assignment

2022-02-03 12:40:49.651 Traceback (most recent call last):
  File "/dados01/workspace/ufmg_2021_f01/ufmg.cmikaela/.local/lib/python3.6/site-packages/streamlit/script_runner.py", line 379, in _run_script
    exec(code, module.__dict__)
  File "/dados01/workspace/ufmg_2021_f01/ufmg.cmikaela/dev/issue-generator/src/app.py", line 112, in <module>
    main(template_issue_coleta, template_issue_generalizacao)
  File "/dados01/workspace/ufmg_2021_f01/ufmg.cmikaela/dev/issue-generator/src/app.py", line 78, in main
    st.write(issues)
UnboundLocalError: local variable 'issues' referenced before assignment

2022-02-03 12:42:59.641 Traceback (most recent call last):
  File "/dados01/workspace/ufmg_2021_f01/ufmg.cmikaela/.local/lib/python3.6/site-packages/streamlit/script_runner.py", line 379, in _run_script
    exec(code, module.__dict__)
  File "/dados01/workspace/ufmg_2021_f01/ufmg.cmikaela/dev/issue-generator/src/app.py", line 112, in <module>
    main(template_issue_coleta, template_issue_generalizacao)
  File "/dados01/workspace/ufmg_2021_f01/ufmg.cmikaela/dev/issue-generator/src/app.py", line 78, in main
    st.write(issues)
UnboundLocalError: local variable 'issues' referenced before assignment

2022-02-03 12:43:02.977 Traceback (most recent call last):
  File "/dados01/workspace/ufmg_2021_f01/ufmg.cmikaela/.local/lib/python3.6/site-packages/streamlit/script_runner.py", line 379, in _run_script
    exec(code, module.__dict__)
  File "/dados01/workspace/ufmg_2021_f01/ufmg.cmikaela/dev/issue-generator/src/app.py", line 112, in <module>
    main(template_issue_coleta, template_issue_generalizacao)
  File "/dados01/workspace/ufmg_2021_f01/ufmg.cmikaela/dev/issue-generator/src/app.py", line 78, in main
    st.write(issues)
UnboundLocalError: local variable 'issues' referenced before assignment

2022-02-03 12:43:19.405 Traceback (most recent call last):
  File "/dados01/workspace/ufmg_2021_f01/ufmg.cmikaela/.local/lib/python3.6/site-packages/streamlit/script_runner.py", line 379, in _run_script
    exec(code, module.__dict__)
  File "/dados01/workspace/ufmg_2021_f01/ufmg.cmikaela/dev/issue-generator/src/app.py", line 112, in <module>
    main(template_issue_coleta, template_issue_generalizacao)
  File "/dados01/workspace/ufmg_2021_f01/ufmg.cmikaela/dev/issue-generator/src/app.py", line 80, in main
    for title, body in issues.items():
UnboundLocalError: local variable 'issues' referenced before assignment

2022-02-03 12:52:38.577 Traceback (most recent call last):
  File "/dados01/workspace/ufmg_2021_f01/ufmg.cmikaela/.local/lib/python3.6/site-packages/streamlit/script_runner.py", line 379, in _run_script
    exec(code, module.__dict__)
  File "/dados01/workspace/ufmg_2021_f01/ufmg.cmikaela/dev/issue-generator/src/app.py", line 117, in <module>
    main(template_issue_coleta, template_issue_generalizacao)
  File "/dados01/workspace/ufmg_2021_f01/ufmg.cmikaela/dev/issue-generator/src/app.py", line 72, in main
    issues = body_text_coleta(template_issue_coleta, data, tag)
  File "/dados01/workspace/ufmg_2021_f01/ufmg.cmikaela/dev/issue-generator/src/app.py", line 15, in body_text_coleta
    template_issue = template_issue.replace("<TAG>", tag)
UnboundLocalError: local variable 'template_issue' referenced before assignment

2022-02-03 12:53:09.290 Traceback (most recent call last):
  File "/dados01/workspace/ufmg_2021_f01/ufmg.cmikaela/.local/lib/python3.6/site-packages/streamlit/script_runner.py", line 379, in _run_script
    exec(code, module.__dict__)
  File "/dados01/workspace/ufmg_2021_f01/ufmg.cmikaela/dev/issue-generator/src/app.py", line 117, in <module>
    main(template_issue_coleta, template_issue_generalizacao)
  File "/dados01/workspace/ufmg_2021_f01/ufmg.cmikaela/dev/issue-generator/src/app.py", line 72, in main
    issues = body_text_coleta(template_issue_coleta, data, tag)
  File "/dados01/workspace/ufmg_2021_f01/ufmg.cmikaela/dev/issue-generator/src/app.py", line 18, in body_text_coleta
    for municipio, link in data.items():
AttributeError: 'list' object has no attribute 'items'

2022-02-03 12:53:32.065 Traceback (most recent call last):
  File "/dados01/workspace/ufmg_2021_f01/ufmg.cmikaela/.local/lib/python3.6/site-packages/streamlit/script_runner.py", line 379, in _run_script
    exec(code, module.__dict__)
  File "/dados01/workspace/ufmg_2021_f01/ufmg.cmikaela/dev/issue-generator/src/app.py", line 119, in <module>
    main(template_issue_coleta, template_issue_generalizacao)
  File "/dados01/workspace/ufmg_2021_f01/ufmg.cmikaela/dev/issue-generator/src/app.py", line 72, in main
    issues = body_text_coleta(template_issue_coleta, data, tag)
  File "/dados01/workspace/ufmg_2021_f01/ufmg.cmikaela/dev/issue-generator/src/app.py", line 18, in body_text_coleta
    for municipio, link in data.items():
AttributeError: 'list' object has no attribute 'items'

2022-02-04 09:40:53.721 Traceback (most recent call last):
  File "/dados01/workspace/ufmg_2021_f01/ufmg.cmikaela/.local/lib/python3.6/site-packages/streamlit/script_runner.py", line 379, in _run_script
    exec(code, module.__dict__)
  File "/dados01/workspace/ufmg_2021_f01/ufmg.cmikaela/dev/issue-generator/src/app.py", line 117, in <module>
    main(template_issue_coleta, template_issue_generalizacao)
  File "/dados01/workspace/ufmg_2021_f01/ufmg.cmikaela/dev/issue-generator/src/app.py", line 85, in main
    for title, body in issues.items():
UnboundLocalError: local variable 'issues' referenced before assignment

2022-02-04 09:40:56.046 Traceback (most recent call last):
  File "/dados01/workspace/ufmg_2021_f01/ufmg.cmikaela/.local/lib/python3.6/site-packages/streamlit/script_runner.py", line 379, in _run_script
    exec(code, module.__dict__)
  File "/dados01/workspace/ufmg_2021_f01/ufmg.cmikaela/dev/issue-generator/src/app.py", line 117, in <module>
    main(template_issue_coleta, template_issue_generalizacao)
  File "/dados01/workspace/ufmg_2021_f01/ufmg.cmikaela/dev/issue-generator/src/app.py", line 85, in main
    for title, body in issues.items():
UnboundLocalError: local variable 'issues' referenced before assignment

2022-02-09 11:13:37.805 Traceback (most recent call last):
  File "/dados01/workspace/ufmg_2021_f01/ufmg.cmikaela/.local/lib/python3.6/site-packages/streamlit/script_runner.py", line 379, in _run_script
    exec(code, module.__dict__)
  File "/dados01/workspace/ufmg_2021_f01/ufmg.cmikaela/dev/issue-generator/src/app.py", line 117, in <module>
    main(template_issue_coleta, template_issue_generalizacao)
  File "/dados01/workspace/ufmg_2021_f01/ufmg.cmikaela/dev/issue-generator/src/app.py", line 67, in main
    data = json.load(uploaded_file)
  File "/usr/lib64/python3.6/json/__init__.py", line 299, in load
    parse_constant=parse_constant, object_pairs_hook=object_pairs_hook, **kw)
  File "/usr/lib64/python3.6/json/__init__.py", line 354, in loads
    return _default_decoder.decode(s)
  File "/usr/lib64/python3.6/json/decoder.py", line 339, in decode
    obj, end = self.raw_decode(s, idx=_w(s, 0).end())
  File "/usr/lib64/python3.6/json/decoder.py", line 355, in raw_decode
    obj, end = self.scan_once(s, idx)
json.decoder.JSONDecodeError: Expecting property name enclosed in double quotes: line 22 column 1 (char 2092)

2022-02-09 11:14:32.865 Traceback (most recent call last):
  File "/dados01/workspace/ufmg_2021_f01/ufmg.cmikaela/.local/lib/python3.6/site-packages/streamlit/script_runner.py", line 379, in _run_script
    exec(code, module.__dict__)
  File "/dados01/workspace/ufmg_2021_f01/ufmg.cmikaela/dev/issue-generator/src/app.py", line 117, in <module>
    main(template_issue_coleta, template_issue_generalizacao)
  File "/dados01/workspace/ufmg_2021_f01/ufmg.cmikaela/dev/issue-generator/src/app.py", line 67, in main
    data = json.load(uploaded_file)
  File "/usr/lib64/python3.6/json/__init__.py", line 299, in load
    parse_constant=parse_constant, object_pairs_hook=object_pairs_hook, **kw)
  File "/usr/lib64/python3.6/json/__init__.py", line 354, in loads
    return _default_decoder.decode(s)
  File "/usr/lib64/python3.6/json/decoder.py", line 339, in decode
    obj, end = self.raw_decode(s, idx=_w(s, 0).end())
  File "/usr/lib64/python3.6/json/decoder.py", line 355, in raw_decode
    obj, end = self.scan_once(s, idx)
json.decoder.JSONDecodeError: Expecting property name enclosed in double quotes: line 22 column 1 (char 2177)

2022-02-09 11:15:18.195 Traceback (most recent call last):
  File "/dados01/workspace/ufmg_2021_f01/ufmg.cmikaela/.local/lib/python3.6/site-packages/streamlit/script_runner.py", line 379, in _run_script
    exec(code, module.__dict__)
  File "/dados01/workspace/ufmg_2021_f01/ufmg.cmikaela/dev/issue-generator/src/app.py", line 117, in <module>
    main(template_issue_coleta, template_issue_generalizacao)
  File "/dados01/workspace/ufmg_2021_f01/ufmg.cmikaela/dev/issue-generator/src/app.py", line 100, in main
    repo = g.get_repo(repo_name)
  File "/dados01/workspace/ufmg_2021_f01/ufmg.cmikaela/.local/lib/python3.6/site-packages/github/MainClass.py", line 330, in get_repo
    headers, data = self.__requester.requestJsonAndCheck("GET", url)
  File "/dados01/workspace/ufmg_2021_f01/ufmg.cmikaela/.local/lib/python3.6/site-packages/github/Requester.py", line 355, in requestJsonAndCheck
    verb, url, parameters, headers, input, self.__customConnection(url)
  File "/dados01/workspace/ufmg_2021_f01/ufmg.cmikaela/.local/lib/python3.6/site-packages/github/Requester.py", line 378, in __check
    raise self.__createException(status, responseHeaders, output)
github.GithubException.UnknownObjectException: 404 {"message": "Not Found", "documentation_url": "https://docs.github.com/rest/reference/repos#get-a-repository"}

2022-02-09 11:25:43.167 Traceback (most recent call last):
  File "/dados01/workspace/ufmg_2021_f01/ufmg.cmikaela/.local/lib/python3.6/site-packages/streamlit/script_runner.py", line 379, in _run_script
    exec(code, module.__dict__)
  File "/dados01/workspace/ufmg_2021_f01/ufmg.cmikaela/dev/issue-generator/src/app.py", line 117, in <module>
    main(template_issue_coleta, template_issue_generalizacao)
  File "/dados01/workspace/ufmg_2021_f01/ufmg.cmikaela/dev/issue-generator/src/app.py", line 85, in main
    for title, body in issues.items():
UnboundLocalError: local variable 'issues' referenced before assignment

2022-02-10 19:54:08.322 Traceback (most recent call last):
  File "/dados01/workspace/ufmg_2021_f01/ufmg.cmikaela/.local/lib/python3.6/site-packages/streamlit/script_runner.py", line 379, in _run_script
    exec(code, module.__dict__)
  File "/dados01/workspace/ufmg_2021_f01/ufmg.cmikaela/dev/issue-generator/src/app.py", line 117, in <module>
    main(template_issue_coleta, template_issue_generalizacao)
  File "/dados01/workspace/ufmg_2021_f01/ufmg.cmikaela/dev/issue-generator/src/app.py", line 67, in main
    data = json.load(uploaded_file)
  File "/usr/lib64/python3.6/json/__init__.py", line 299, in load
    parse_constant=parse_constant, object_pairs_hook=object_pairs_hook, **kw)
  File "/usr/lib64/python3.6/json/__init__.py", line 354, in loads
    return _default_decoder.decode(s)
  File "/usr/lib64/python3.6/json/decoder.py", line 339, in decode
    obj, end = self.raw_decode(s, idx=_w(s, 0).end())
  File "/usr/lib64/python3.6/json/decoder.py", line 355, in raw_decode
    obj, end = self.scan_once(s, idx)
json.decoder.JSONDecodeError: Expecting property name enclosed in double quotes: line 21 column 1 (char 2295)

2022-02-10 19:57:15.671 Traceback (most recent call last):
  File "/dados01/workspace/ufmg_2021_f01/ufmg.cmikaela/.local/lib/python3.6/site-packages/streamlit/script_runner.py", line 379, in _run_script
    exec(code, module.__dict__)
  File "/dados01/workspace/ufmg_2021_f01/ufmg.cmikaela/dev/issue-generator/src/app.py", line 117, in <module>
    main(template_issue_coleta, template_issue_generalizacao)
  File "/dados01/workspace/ufmg_2021_f01/ufmg.cmikaela/dev/issue-generator/src/app.py", line 100, in main
    repo = g.get_repo(repo_name)
  File "/dados01/workspace/ufmg_2021_f01/ufmg.cmikaela/.local/lib/python3.6/site-packages/github/MainClass.py", line 330, in get_repo
    headers, data = self.__requester.requestJsonAndCheck("GET", url)
  File "/dados01/workspace/ufmg_2021_f01/ufmg.cmikaela/.local/lib/python3.6/site-packages/github/Requester.py", line 355, in requestJsonAndCheck
    verb, url, parameters, headers, input, self.__customConnection(url)
  File "/dados01/workspace/ufmg_2021_f01/ufmg.cmikaela/.local/lib/python3.6/site-packages/github/Requester.py", line 378, in __check
    raise self.__createException(status, responseHeaders, output)
github.GithubException.UnknownObjectException: 404 {"message": "Not Found", "documentation_url": "https://docs.github.com/rest/reference/repos#get-a-repository"}

2022-02-10 20:01:08.026 Traceback (most recent call last):
  File "/dados01/workspace/ufmg_2021_f01/ufmg.cmikaela/.local/lib/python3.6/site-packages/streamlit/script_runner.py", line 379, in _run_script
    exec(code, module.__dict__)
  File "/dados01/workspace/ufmg_2021_f01/ufmg.cmikaela/dev/issue-generator/src/app.py", line 117, in <module>
    main(template_issue_coleta, template_issue_generalizacao)
  File "/dados01/workspace/ufmg_2021_f01/ufmg.cmikaela/dev/issue-generator/src/app.py", line 100, in main
    repo = g.get_repo(repo_name)
  File "/dados01/workspace/ufmg_2021_f01/ufmg.cmikaela/.local/lib/python3.6/site-packages/github/MainClass.py", line 330, in get_repo
    headers, data = self.__requester.requestJsonAndCheck("GET", url)
  File "/dados01/workspace/ufmg_2021_f01/ufmg.cmikaela/.local/lib/python3.6/site-packages/github/Requester.py", line 355, in requestJsonAndCheck
    verb, url, parameters, headers, input, self.__customConnection(url)
  File "/dados01/workspace/ufmg_2021_f01/ufmg.cmikaela/.local/lib/python3.6/site-packages/github/Requester.py", line 378, in __check
    raise self.__createException(status, responseHeaders, output)
github.GithubException.UnknownObjectException: 404 {"message": "Not Found", "documentation_url": "https://docs.github.com/rest/reference/repos#get-a-repository"}

2022-02-10 20:05:02.543 Traceback (most recent call last):
  File "/dados01/workspace/ufmg_2021_f01/ufmg.cmikaela/.local/lib/python3.6/site-packages/streamlit/script_runner.py", line 379, in _run_script
    exec(code, module.__dict__)
  File "/dados01/workspace/ufmg_2021_f01/ufmg.cmikaela/dev/issue-generator/src/app.py", line 117, in <module>
    main(template_issue_coleta, template_issue_generalizacao)
  File "/dados01/workspace/ufmg_2021_f01/ufmg.cmikaela/dev/issue-generator/src/app.py", line 67, in main
    data = json.load(uploaded_file)
  File "/usr/lib64/python3.6/json/__init__.py", line 299, in load
    parse_constant=parse_constant, object_pairs_hook=object_pairs_hook, **kw)
  File "/usr/lib64/python3.6/json/__init__.py", line 354, in loads
    return _default_decoder.decode(s)
  File "/usr/lib64/python3.6/json/decoder.py", line 339, in decode
    obj, end = self.raw_decode(s, idx=_w(s, 0).end())
  File "/usr/lib64/python3.6/json/decoder.py", line 355, in raw_decode
    obj, end = self.scan_once(s, idx)
json.decoder.JSONDecodeError: Expecting property name enclosed in double quotes: line 6 column 1 (char 565)

2022-02-10 21:57:05.609 Traceback (most recent call last):
  File "/dados01/workspace/ufmg_2021_f01/ufmg.cmikaela/.local/lib/python3.6/site-packages/streamlit/script_runner.py", line 379, in _run_script
    exec(code, module.__dict__)
  File "/dados01/workspace/ufmg_2021_f01/ufmg.cmikaela/dev/issue-generator/src/app.py", line 117, in <module>
    main(template_issue_coleta, template_issue_generalizacao)
  File "/dados01/workspace/ufmg_2021_f01/ufmg.cmikaela/dev/issue-generator/src/app.py", line 85, in main
    for title, body in issues.items():
UnboundLocalError: local variable 'issues' referenced before assignment

2022-02-10 22:04:57.513 Traceback (most recent call last):
  File "/dados01/workspace/ufmg_2021_f01/ufmg.cmikaela/.local/lib/python3.6/site-packages/streamlit/script_runner.py", line 379, in _run_script
    exec(code, module.__dict__)
  File "/dados01/workspace/ufmg_2021_f01/ufmg.cmikaela/dev/issue-generator/src/app.py", line 117, in <module>
    main(template_issue_coleta, template_issue_generalizacao)
  File "/dados01/workspace/ufmg_2021_f01/ufmg.cmikaela/dev/issue-generator/src/app.py", line 100, in main
    repo = g.get_repo(repo_name)
  File "/dados01/workspace/ufmg_2021_f01/ufmg.cmikaela/.local/lib/python3.6/site-packages/github/MainClass.py", line 330, in get_repo
    headers, data = self.__requester.requestJsonAndCheck("GET", url)
  File "/dados01/workspace/ufmg_2021_f01/ufmg.cmikaela/.local/lib/python3.6/site-packages/github/Requester.py", line 355, in requestJsonAndCheck
    verb, url, parameters, headers, input, self.__customConnection(url)
  File "/dados01/workspace/ufmg_2021_f01/ufmg.cmikaela/.local/lib/python3.6/site-packages/github/Requester.py", line 378, in __check
    raise self.__createException(status, responseHeaders, output)
github.GithubException.UnknownObjectException: 404 {"message": "Not Found", "documentation_url": "https://docs.github.com/rest/reference/repos#get-a-repository"}

2022-02-10 22:23:59.110 Traceback (most recent call last):
  File "/dados01/workspace/ufmg_2021_f01/ufmg.cmikaela/.local/lib/python3.6/site-packages/streamlit/script_runner.py", line 379, in _run_script
    exec(code, module.__dict__)
  File "/dados01/workspace/ufmg_2021_f01/ufmg.cmikaela/dev/issue-generator/src/app.py", line 117, in <module>
    main(template_issue_coleta, template_issue_generalizacao)
  File "/dados01/workspace/ufmg_2021_f01/ufmg.cmikaela/dev/issue-generator/src/app.py", line 85, in main
    for title, body in issues.items():
UnboundLocalError: local variable 'issues' referenced before assignment

2022-02-10 22:24:01.181 Traceback (most recent call last):
  File "/dados01/workspace/ufmg_2021_f01/ufmg.cmikaela/.local/lib/python3.6/site-packages/streamlit/script_runner.py", line 379, in _run_script
    exec(code, module.__dict__)
  File "/dados01/workspace/ufmg_2021_f01/ufmg.cmikaela/dev/issue-generator/src/app.py", line 117, in <module>
    main(template_issue_coleta, template_issue_generalizacao)
  File "/dados01/workspace/ufmg_2021_f01/ufmg.cmikaela/dev/issue-generator/src/app.py", line 85, in main
    for title, body in issues.items():
UnboundLocalError: local variable 'issues' referenced before assignment

Usage: streamlit run [OPTIONS] TARGET [ARGS]...
Try 'streamlit run --help' for help.

Error: No such option: --port Did you mean --server.port?

  You can now view your Streamlit app in your browser.

  Network URL: http://10.21.0.126:8060
  External URL: http://177.190.215.14:8060

