
  You can now view your Streamlit app in your browser.

  Network URL: http://10.21.0.126:8040
  External URL: http://177.190.215.14:8040

/dados01/workspace/ufmg_2021_f01/ufmg.cmikaela/.local/lib/python3.6/site-packages/streamlit/bootstrap.py:110: UserWarning: 
This call to matplotlib.use() has no effect because the backend has already
been chosen; matplotlib.use() must be called *before* pylab, matplotlib.pyplot,
or matplotlib.backends is imported for the first time.

The backend was *originally* set to 'TkAgg' by the following code:
  File "/dados01/workspace/ufmg_2021_f01/ufmg.cmikaela/.local/bin/streamlit", line 5, in <module>
    from streamlit.cli import main
  File "/dados01/workspace/ufmg_2021_f01/ufmg.cmikaela/.local/lib/python3.6/site-packages/streamlit/__init__.py", line 72, in <module>
    from streamlit.delta_generator import DeltaGenerator as _DeltaGenerator
  File "/dados01/workspace/ufmg_2021_f01/ufmg.cmikaela/.local/lib/python3.6/site-packages/streamlit/delta_generator.py", line 71, in <module>
    from streamlit.elements.arrow import ArrowMixin
  File "/dados01/workspace/ufmg_2021_f01/ufmg.cmikaela/.local/lib/python3.6/site-packages/streamlit/elements/arrow.py", line 20, in <module>
    from pandas.io.formats.style import Styler
  File "/dados01/workspace/ufmg_2021_f01/ufmg.cmikaela/.local/lib/python3.6/site-packages/pandas/io/formats/style.py", line 46, in <module>
    import matplotlib.pyplot as plt
  File "/usr/local/lib64/python3.6/site-packages/matplotlib/pyplot.py", line 71, in <module>
    from matplotlib.backends import pylab_setup
  File "/usr/local/lib64/python3.6/site-packages/matplotlib/backends/__init__.py", line 17, in <module>
    line for line in traceback.format_stack()


  matplotlib.use("Agg")
2022-02-04 19:01:58.575 Traceback (most recent call last):
  File "/dados01/workspace/ufmg_2021_f01/ufmg.cmikaela/.local/lib/python3.6/site-packages/streamlit/script_runner.py", line 379, in _run_script
    exec(code, module.__dict__)
  File "/dados01/workspace/ufmg_2021_f01/ufmg.cmikaela/dev/config-coleta-generator/app.py", line 110, in <module>
    main()
  File "/dados01/workspace/ufmg_2021_f01/ufmg.cmikaela/dev/config-coleta-generator/app.py", line 92, in main
    for nome_municipio, _ in configs.items():
AttributeError: 'list' object has no attribute 'items'

2022-02-04 19:20:20.706 Traceback (most recent call last):
  File "/dados01/workspace/ufmg_2021_f01/ufmg.cmikaela/.local/lib/python3.6/site-packages/streamlit/script_runner.py", line 379, in _run_script
    exec(code, module.__dict__)
  File "/dados01/workspace/ufmg_2021_f01/ufmg.cmikaela/dev/config-coleta-generator/app.py", line 108, in <module>
    main()
  File "/dados01/workspace/ufmg_2021_f01/ufmg.cmikaela/dev/config-coleta-generator/app.py", line 91, in main
    with open('{}_{}_{}/config_{}.json'.format(template_name, tag, subtag, nome_municipio), 'w') as f:
FileNotFoundError: [Errno 2] No such file or directory: 'Sintese Tecnologia e Informacao_Despesas_Contas Públicas/config_Chapada Gaúcha.json'

2022-02-04 19:23:57.752 Traceback (most recent call last):
  File "/dados01/workspace/ufmg_2021_f01/ufmg.cmikaela/.local/lib/python3.6/site-packages/streamlit/script_runner.py", line 379, in _run_script
    exec(code, module.__dict__)
  File "/dados01/workspace/ufmg_2021_f01/ufmg.cmikaela/dev/config-coleta-generator/app.py", line 110, in <module>
    main()
  File "/dados01/workspace/ufmg_2021_f01/ufmg.cmikaela/dev/config-coleta-generator/app.py", line 86, in main
    configs = fill_config_file(template, config, tag, subtag, url_base)
  File "/dados01/workspace/ufmg_2021_f01/ufmg.cmikaela/dev/config-coleta-generator/app.py", line 54, in fill_config_file
    st.write(configs[9])
IndexError: list index out of range

2022-02-04 19:26:40.579 Traceback (most recent call last):
  File "/dados01/workspace/ufmg_2021_f01/ufmg.cmikaela/.local/lib/python3.6/site-packages/streamlit/script_runner.py", line 379, in _run_script
    exec(code, module.__dict__)
  File "/dados01/workspace/ufmg_2021_f01/ufmg.cmikaela/dev/config-coleta-generator/app.py", line 108, in <module>
    main()
  File "/dados01/workspace/ufmg_2021_f01/ufmg.cmikaela/dev/config-coleta-generator/app.py", line 84, in main
    configs = fill_config_file(template, config, tag, subtag, url_base)
  File "/dados01/workspace/ufmg_2021_f01/ufmg.cmikaela/dev/config-coleta-generator/app.py", line 43, in fill_config_file
    data = source_name_replace(template, tag, subtag, nome_municipio)
  File "/dados01/workspace/ufmg_2021_f01/ufmg.cmikaela/dev/config-coleta-generator/app.py", line 20, in source_name_replace
    return data
NameError: name 'data' is not defined

2022-02-04 19:26:53.990 Traceback (most recent call last):
  File "/dados01/workspace/ufmg_2021_f01/ufmg.cmikaela/.local/lib/python3.6/site-packages/streamlit/script_runner.py", line 379, in _run_script
    exec(code, module.__dict__)
  File "/dados01/workspace/ufmg_2021_f01/ufmg.cmikaela/dev/config-coleta-generator/app.py", line 108, in <module>
    main()
  File "/dados01/workspace/ufmg_2021_f01/ufmg.cmikaela/dev/config-coleta-generator/app.py", line 84, in main
    configs = fill_config_file(template, config, tag, subtag, url_base)
  File "/dados01/workspace/ufmg_2021_f01/ufmg.cmikaela/dev/config-coleta-generator/app.py", line 49, in fill_config_file
    data = data_path_replace(data, tag, subtag, value)
  File "/dados01/workspace/ufmg_2021_f01/ufmg.cmikaela/dev/config-coleta-generator/app.py", line 24, in data_path_replace
    aux['data_path'] = aux['data_path'].replace("<TAG>", tag)
NameError: name 'aux' is not defined

2022-02-04 19:26:57.900 Traceback (most recent call last):
  File "/dados01/workspace/ufmg_2021_f01/ufmg.cmikaela/.local/lib/python3.6/site-packages/streamlit/script_runner.py", line 379, in _run_script
    exec(code, module.__dict__)
  File "/dados01/workspace/ufmg_2021_f01/ufmg.cmikaela/dev/config-coleta-generator/app.py", line 108, in <module>
    main()
  File "/dados01/workspace/ufmg_2021_f01/ufmg.cmikaela/dev/config-coleta-generator/app.py", line 84, in main
    configs = fill_config_file(template, config, tag, subtag, url_base)
  File "/dados01/workspace/ufmg_2021_f01/ufmg.cmikaela/dev/config-coleta-generator/app.py", line 49, in fill_config_file
    data = data_path_replace(data, tag, subtag, value)
  File "/dados01/workspace/ufmg_2021_f01/ufmg.cmikaela/dev/config-coleta-generator/app.py", line 24, in data_path_replace
    aux['data_path'] = aux['data_path'].replace("<TAG>", tag)
NameError: name 'aux' is not defined

2022-02-04 19:27:24.550 Traceback (most recent call last):
  File "/dados01/workspace/ufmg_2021_f01/ufmg.cmikaela/.local/lib/python3.6/site-packages/streamlit/script_runner.py", line 379, in _run_script
    exec(code, module.__dict__)
  File "/dados01/workspace/ufmg_2021_f01/ufmg.cmikaela/dev/config-coleta-generator/app.py", line 111, in <module>
    main()
  File "/dados01/workspace/ufmg_2021_f01/ufmg.cmikaela/dev/config-coleta-generator/app.py", line 87, in main
    configs = fill_config_file(template, config, tag, subtag, url_base)
  File "/dados01/workspace/ufmg_2021_f01/ufmg.cmikaela/dev/config-coleta-generator/app.py", line 46, in fill_config_file
    data = source_name_replace(template, tag, subtag, nome_municipio)
  File "/dados01/workspace/ufmg_2021_f01/ufmg.cmikaela/dev/config-coleta-generator/app.py", line 16, in source_name_replace
    aux = data
NameError: name 'data' is not defined

2022-02-04 22:02:09.519 Traceback (most recent call last):
  File "/dados01/workspace/ufmg_2021_f01/ufmg.cmikaela/.local/lib/python3.6/site-packages/streamlit/script_runner.py", line 379, in _run_script
    exec(code, module.__dict__)
  File "/dados01/workspace/ufmg_2021_f01/ufmg.cmikaela/dev/config-coleta-generator/app.py", line 107, in <module>
    main()
  File "/dados01/workspace/ufmg_2021_f01/ufmg.cmikaela/dev/config-coleta-generator/app.py", line 83, in main
    configs = fill_config_file(template, config, tag, subtag, url_base)
  File "/dados01/workspace/ufmg_2021_f01/ufmg.cmikaela/dev/config-coleta-generator/app.py", line 44, in fill_config_file
    for key, value in parametros.items():
AttributeError: 'str' object has no attribute 'items'

2022-02-04 22:02:20.464 Traceback (most recent call last):
  File "/dados01/workspace/ufmg_2021_f01/ufmg.cmikaela/.local/lib/python3.6/site-packages/streamlit/script_runner.py", line 379, in _run_script
    exec(code, module.__dict__)
  File "/dados01/workspace/ufmg_2021_f01/ufmg.cmikaela/dev/config-coleta-generator/app.py", line 107, in <module>
    main()
  File "/dados01/workspace/ufmg_2021_f01/ufmg.cmikaela/dev/config-coleta-generator/app.py", line 83, in main
    configs = fill_config_file(template, config, tag, subtag, url_base)
  File "/dados01/workspace/ufmg_2021_f01/ufmg.cmikaela/dev/config-coleta-generator/app.py", line 44, in fill_config_file
    for key, value in parametros.items():
AttributeError: 'str' object has no attribute 'items'

2022-02-04 22:02:22.273 Traceback (most recent call last):
  File "/dados01/workspace/ufmg_2021_f01/ufmg.cmikaela/.local/lib/python3.6/site-packages/streamlit/script_runner.py", line 379, in _run_script
    exec(code, module.__dict__)
  File "/dados01/workspace/ufmg_2021_f01/ufmg.cmikaela/dev/config-coleta-generator/app.py", line 107, in <module>
    main()
  File "/dados01/workspace/ufmg_2021_f01/ufmg.cmikaela/dev/config-coleta-generator/app.py", line 83, in main
    configs = fill_config_file(template, config, tag, subtag, url_base)
  File "/dados01/workspace/ufmg_2021_f01/ufmg.cmikaela/dev/config-coleta-generator/app.py", line 44, in fill_config_file
    for key, value in parametros.items():
AttributeError: 'str' object has no attribute 'items'

2022-02-04 22:03:30.187 Traceback (most recent call last):
  File "/dados01/workspace/ufmg_2021_f01/ufmg.cmikaela/.local/lib/python3.6/site-packages/streamlit/script_runner.py", line 379, in _run_script
    exec(code, module.__dict__)
  File "/dados01/workspace/ufmg_2021_f01/ufmg.cmikaela/dev/config-coleta-generator/app.py", line 107, in <module>
    main()
  File "/dados01/workspace/ufmg_2021_f01/ufmg.cmikaela/dev/config-coleta-generator/app.py", line 83, in main
    configs = fill_config_file(template, config, tag, subtag, url_base)
  File "/dados01/workspace/ufmg_2021_f01/ufmg.cmikaela/dev/config-coleta-generator/app.py", line 44, in fill_config_file
    for key, value in parametros.items():
AttributeError: 'str' object has no attribute 'items'

2022-02-04 22:07:45.384 Traceback (most recent call last):
  File "/dados01/workspace/ufmg_2021_f01/ufmg.cmikaela/.local/lib/python3.6/site-packages/streamlit/script_runner.py", line 379, in _run_script
    exec(code, module.__dict__)
  File "/dados01/workspace/ufmg_2021_f01/ufmg.cmikaela/dev/config-coleta-generator/app.py", line 107, in <module>
    main()
  File "/dados01/workspace/ufmg_2021_f01/ufmg.cmikaela/dev/config-coleta-generator/app.py", line 83, in main
    configs = fill_config_file(template, config, tag, subtag, url_base)
  File "/dados01/workspace/ufmg_2021_f01/ufmg.cmikaela/dev/config-coleta-generator/app.py", line 44, in fill_config_file
    for key, value in parametros.items():
AttributeError: 'str' object has no attribute 'items'

2022-02-04 22:10:07.185 Traceback (most recent call last):
  File "/dados01/workspace/ufmg_2021_f01/ufmg.cmikaela/.local/lib/python3.6/site-packages/streamlit/script_runner.py", line 379, in _run_script
    exec(code, module.__dict__)
  File "/dados01/workspace/ufmg_2021_f01/ufmg.cmikaela/dev/config-coleta-generator/app.py", line 107, in <module>
    main()
  File "/dados01/workspace/ufmg_2021_f01/ufmg.cmikaela/dev/config-coleta-generator/app.py", line 83, in main
    configs = fill_config_file(template, config, tag, subtag, url_base)
  File "/dados01/workspace/ufmg_2021_f01/ufmg.cmikaela/dev/config-coleta-generator/app.py", line 44, in fill_config_file
    for key, value in parametros.items():
AttributeError: 'str' object has no attribute 'items'

2022-02-04 22:10:23.571 Traceback (most recent call last):
  File "/dados01/workspace/ufmg_2021_f01/ufmg.cmikaela/.local/lib/python3.6/site-packages/streamlit/script_runner.py", line 379, in _run_script
    exec(code, module.__dict__)
  File "/dados01/workspace/ufmg_2021_f01/ufmg.cmikaela/dev/config-coleta-generator/app.py", line 107, in <module>
    main()
  File "/dados01/workspace/ufmg_2021_f01/ufmg.cmikaela/dev/config-coleta-generator/app.py", line 83, in main
    configs = fill_config_file(template, config, tag, subtag, url_base)
  File "/dados01/workspace/ufmg_2021_f01/ufmg.cmikaela/dev/config-coleta-generator/app.py", line 44, in fill_config_file
    for key, value in parametros.items():
AttributeError: 'str' object has no attribute 'items'

2022-02-04 22:12:27.774 Traceback (most recent call last):
  File "/dados01/workspace/ufmg_2021_f01/ufmg.cmikaela/.local/lib/python3.6/site-packages/streamlit/script_runner.py", line 379, in _run_script
    exec(code, module.__dict__)
  File "/dados01/workspace/ufmg_2021_f01/ufmg.cmikaela/dev/config-coleta-generator/app.py", line 107, in <module>
    main()
  File "/dados01/workspace/ufmg_2021_f01/ufmg.cmikaela/dev/config-coleta-generator/app.py", line 83, in main
    configs = fill_config_file(template, config, tag, subtag, url_base)
  File "/dados01/workspace/ufmg_2021_f01/ufmg.cmikaela/dev/config-coleta-generator/app.py", line 44, in fill_config_file
    for key, value in parametros.items():
AttributeError: 'str' object has no attribute 'items'

2022-02-04 22:13:58.256 Traceback (most recent call last):
  File "/dados01/workspace/ufmg_2021_f01/ufmg.cmikaela/.local/lib/python3.6/site-packages/streamlit/script_runner.py", line 379, in _run_script
    exec(code, module.__dict__)
  File "/dados01/workspace/ufmg_2021_f01/ufmg.cmikaela/dev/config-coleta-generator/app.py", line 107, in <module>
    main()
  File "/dados01/workspace/ufmg_2021_f01/ufmg.cmikaela/dev/config-coleta-generator/app.py", line 83, in main
    configs = fill_config_file(template, config, tag, subtag, url_base)
  File "/dados01/workspace/ufmg_2021_f01/ufmg.cmikaela/dev/config-coleta-generator/app.py", line 44, in fill_config_file
    for key, value in parametros.items():
AttributeError: 'str' object has no attribute 'items'

2022-02-04 22:17:03.231 Traceback (most recent call last):
  File "/dados01/workspace/ufmg_2021_f01/ufmg.cmikaela/.local/lib/python3.6/site-packages/streamlit/script_runner.py", line 379, in _run_script
    exec(code, module.__dict__)
  File "/dados01/workspace/ufmg_2021_f01/ufmg.cmikaela/dev/config-coleta-generator/app.py", line 107, in <module>
    main()
  File "/dados01/workspace/ufmg_2021_f01/ufmg.cmikaela/dev/config-coleta-generator/app.py", line 83, in main
    configs = fill_config_file(template, config, tag, subtag, url_base)
  File "/dados01/workspace/ufmg_2021_f01/ufmg.cmikaela/dev/config-coleta-generator/app.py", line 44, in fill_config_file
    for key, value in parametros.items():
AttributeError: 'str' object has no attribute 'items'

2022-02-14 14:33:43.464 Traceback (most recent call last):
  File "/dados01/workspace/ufmg_2021_f01/ufmg.cmikaela/.local/lib/python3.6/site-packages/streamlit/script_runner.py", line 379, in _run_script
    exec(code, module.__dict__)
  File "/dados01/workspace/ufmg_2021_f01/ufmg.cmikaela/dev/config-coleta-generator/app.py", line 130, in <module>
    main()
  File "/dados01/workspace/ufmg_2021_f01/ufmg.cmikaela/dev/config-coleta-generator/app.py", line 103, in main
    configs = fill_config_file(template, config, tag, subtag, url_base)
  File "/dados01/workspace/ufmg_2021_f01/ufmg.cmikaela/dev/config-coleta-generator/app.py", line 50, in fill_config_file
    data = base_url_replace(data, url_base, value)
  File "/dados01/workspace/ufmg_2021_f01/ufmg.cmikaela/dev/config-coleta-generator/app.py", line 39, in base_url_replace
    return datas
NameError: name 'datas' is not defined

2022-02-14 14:35:28.752 Traceback (most recent call last):
  File "/dados01/workspace/ufmg_2021_f01/ufmg.cmikaela/.local/lib/python3.6/site-packages/streamlit/script_runner.py", line 379, in _run_script
    exec(code, module.__dict__)
  File "/dados01/workspace/ufmg_2021_f01/ufmg.cmikaela/dev/config-coleta-generator/app.py", line 130, in <module>
    main()
  File "/dados01/workspace/ufmg_2021_f01/ufmg.cmikaela/dev/config-coleta-generator/app.py", line 103, in main
    configs = fill_config_file(template, config, tag, subtag, url_base)
  File "/dados01/workspace/ufmg_2021_f01/ufmg.cmikaela/dev/config-coleta-generator/app.py", line 52, in fill_config_file
    data = data_path_replace(data, tag, subtag, value)
  File "/dados01/workspace/ufmg_2021_f01/ufmg.cmikaela/dev/config-coleta-generator/app.py", line 28, in data_path_replace
    data['source_name'] = data['source_name'].replace("<TAG>", unidecode(tag).lower())
NameError: name 'unidecode' is not defined

2022-02-14 14:36:10.316 Traceback (most recent call last):
  File "/dados01/workspace/ufmg_2021_f01/ufmg.cmikaela/.local/lib/python3.6/site-packages/streamlit/script_runner.py", line 379, in _run_script
    exec(code, module.__dict__)
  File "/dados01/workspace/ufmg_2021_f01/ufmg.cmikaela/dev/config-coleta-generator/app.py", line 13, in <module>
    import unidecode
ModuleNotFoundError: No module named 'unidecode'

2022-02-14 14:39:13.558 Traceback (most recent call last):
  File "/dados01/workspace/ufmg_2021_f01/ufmg.cmikaela/.local/lib/python3.6/site-packages/streamlit/script_runner.py", line 379, in _run_script
    exec(code, module.__dict__)
  File "/dados01/workspace/ufmg_2021_f01/ufmg.cmikaela/dev/config-coleta-generator/app.py", line 130, in <module>
    main()
  File "/dados01/workspace/ufmg_2021_f01/ufmg.cmikaela/dev/config-coleta-generator/app.py", line 103, in main
    configs = fill_config_file(template, config, tag, subtag, url_base)
  File "/dados01/workspace/ufmg_2021_f01/ufmg.cmikaela/dev/config-coleta-generator/app.py", line 52, in fill_config_file
    data = data_path_replace(data, tag, subtag, value)
  File "/dados01/workspace/ufmg_2021_f01/ufmg.cmikaela/dev/config-coleta-generator/app.py", line 28, in data_path_replace
    data['source_name'] = data['source_name'].replace("<TAG>", unidecode(tag).lower())
TypeError: 'module' object is not callable

2022-02-14 14:39:42.288 Traceback (most recent call last):
  File "/dados01/workspace/ufmg_2021_f01/ufmg.cmikaela/.local/lib/python3.6/site-packages/streamlit/script_runner.py", line 379, in _run_script
    exec(code, module.__dict__)
  File "/dados01/workspace/ufmg_2021_f01/ufmg.cmikaela/dev/config-coleta-generator/app.py", line 130, in <module>
    main()
  File "/dados01/workspace/ufmg_2021_f01/ufmg.cmikaela/dev/config-coleta-generator/app.py", line 103, in main
    configs = fill_config_file(template, config, tag, subtag, url_base)
  File "/dados01/workspace/ufmg_2021_f01/ufmg.cmikaela/dev/config-coleta-generator/app.py", line 52, in fill_config_file
    data = data_path_replace(data, tag, subtag, value)
  File "/dados01/workspace/ufmg_2021_f01/ufmg.cmikaela/dev/config-coleta-generator/app.py", line 28, in data_path_replace
    data['source_name'] = data['source_name'].replace("<TAG>", unidecode(tag).lower())
TypeError: 'module' object is not callable

2022-02-14 14:39:58.356 Traceback (most recent call last):
  File "/dados01/workspace/ufmg_2021_f01/ufmg.cmikaela/.local/lib/python3.6/site-packages/streamlit/script_runner.py", line 379, in _run_script
    exec(code, module.__dict__)
  File "/dados01/workspace/ufmg_2021_f01/ufmg.cmikaela/dev/config-coleta-generator/app.py", line 130, in <module>
    main()
  File "/dados01/workspace/ufmg_2021_f01/ufmg.cmikaela/dev/config-coleta-generator/app.py", line 103, in main
    configs = fill_config_file(template, config, tag, subtag, url_base)
  File "/dados01/workspace/ufmg_2021_f01/ufmg.cmikaela/dev/config-coleta-generator/app.py", line 52, in fill_config_file
    data = data_path_replace(data, tag, subtag, value)
  File "/dados01/workspace/ufmg_2021_f01/ufmg.cmikaela/dev/config-coleta-generator/app.py", line 28, in data_path_replace
    data['source_name'] = data['source_name'].replace("<TAG>", unidecode(tag))
TypeError: 'module' object is not callable

2022-02-14 14:45:00.940 Traceback (most recent call last):
  File "/dados01/workspace/ufmg_2021_f01/ufmg.cmikaela/.local/lib/python3.6/site-packages/streamlit/script_runner.py", line 379, in _run_script
    exec(code, module.__dict__)
  File "/dados01/workspace/ufmg_2021_f01/ufmg.cmikaela/dev/config-coleta-generator/app.py", line 133, in <module>
    main()
  File "/dados01/workspace/ufmg_2021_f01/ufmg.cmikaela/dev/config-coleta-generator/app.py", line 128, in main
    logtxtbox.text_area("Conteúdo da Issue: ", cofig[0], height=700)
NameError: name 'cofig' is not defined

2022-02-14 14:45:12.459 Traceback (most recent call last):
  File "/dados01/workspace/ufmg_2021_f01/ufmg.cmikaela/.local/lib/python3.6/site-packages/streamlit/script_runner.py", line 379, in _run_script
    exec(code, module.__dict__)
  File "/dados01/workspace/ufmg_2021_f01/ufmg.cmikaela/dev/config-coleta-generator/app.py", line 133, in <module>
    main()
  File "/dados01/workspace/ufmg_2021_f01/ufmg.cmikaela/dev/config-coleta-generator/app.py", line 128, in main
    logtxtbox.text_area("Conteúdo da Issue: ", config[0], height=700)
KeyError: 0

2022-02-14 14:51:07.705 Traceback (most recent call last):
  File "/dados01/workspace/ufmg_2021_f01/ufmg.cmikaela/.local/lib/python3.6/site-packages/streamlit/script_runner.py", line 379, in _run_script
    exec(code, module.__dict__)
  File "/dados01/workspace/ufmg_2021_f01/ufmg.cmikaela/dev/config-coleta-generator/app.py", line 141, in <module>
    main()
  File "/dados01/workspace/ufmg_2021_f01/ufmg.cmikaela/dev/config-coleta-generator/app.py", line 98, in main
    config = json.load(config_file)
  File "/usr/lib64/python3.6/json/__init__.py", line 299, in load
    parse_constant=parse_constant, object_pairs_hook=object_pairs_hook, **kw)
  File "/usr/lib64/python3.6/json/__init__.py", line 354, in loads
    return _default_decoder.decode(s)
  File "/usr/lib64/python3.6/json/decoder.py", line 339, in decode
    obj, end = self.raw_decode(s, idx=_w(s, 0).end())
  File "/usr/lib64/python3.6/json/decoder.py", line 355, in raw_decode
    obj, end = self.scan_once(s, idx)
json.decoder.JSONDecodeError: Expecting property name enclosed in double quotes: line 6 column 1 (char 268)

2022-02-14 14:52:23.848 Traceback (most recent call last):
  File "/dados01/workspace/ufmg_2021_f01/ufmg.cmikaela/.local/lib/python3.6/site-packages/streamlit/script_runner.py", line 379, in _run_script
    exec(code, module.__dict__)
  File "/dados01/workspace/ufmg_2021_f01/ufmg.cmikaela/dev/config-coleta-generator/app.py", line 139, in <module>
    main()
  File "/dados01/workspace/ufmg_2021_f01/ufmg.cmikaela/dev/config-coleta-generator/app.py", line 134, in main
    for i in range(len(configs)):
UnboundLocalError: local variable 'configs' referenced before assignment

2022-02-15 13:47:24.850 Traceback (most recent call last):
  File "/dados01/workspace/ufmg_2021_f01/ufmg.cmikaela/.local/lib/python3.6/site-packages/streamlit/script_runner.py", line 379, in _run_script
    exec(code, module.__dict__)
  File "/dados01/workspace/ufmg_2021_f01/ufmg.cmikaela/dev/config-coleta-generator/app.py", line 139, in <module>
    main()
  File "/dados01/workspace/ufmg_2021_f01/ufmg.cmikaela/dev/config-coleta-generator/app.py", line 135, in main
    create_and_run_coletor(i)
  File "/dados01/workspace/ufmg_2021_f01/ufmg.cmikaela/dev/config-coleta-generator/app.py", line 66, in create_and_run_coletor
    id_crawler = configuracao_do_coletor_criado['id']
KeyError: 'id'

2022-02-15 15:49:01.990 Traceback (most recent call last):
  File "/dados01/workspace/ufmg_2021_f01/ufmg.cmikaela/.local/lib/python3.6/site-packages/streamlit/script_runner.py", line 379, in _run_script
    exec(code, module.__dict__)
  File "/dados01/workspace/ufmg_2021_f01/ufmg.cmikaela/dev/config-coleta-generator/app.py", line 139, in <module>
    main()
  File "/dados01/workspace/ufmg_2021_f01/ufmg.cmikaela/dev/config-coleta-generator/app.py", line 104, in main
    configs = fill_config_file(template, config, tag, subtag, url_base)
UnboundLocalError: local variable 'template' referenced before assignment

2022-02-15 17:13:15.615 Traceback (most recent call last):
  File "/dados01/workspace/ufmg_2021_f01/ufmg.cmikaela/.local/lib/python3.6/site-packages/streamlit/script_runner.py", line 379, in _run_script
    exec(code, module.__dict__)
  File "/dados01/workspace/ufmg_2021_f01/ufmg.cmikaela/dev/config-coleta-generator/app.py", line 141, in <module>
    "App2": app2
NameError: name 'app2' is not defined

2022-02-15 17:14:02.479 Traceback (most recent call last):
  File "/dados01/workspace/ufmg_2021_f01/ufmg.cmikaela/.local/lib/python3.6/site-packages/streamlit/script_runner.py", line 379, in _run_script
    exec(code, module.__dict__)
  File "/dados01/workspace/ufmg_2021_f01/ufmg.cmikaela/dev/config-coleta-generator/app.py", line 148, in <module>
    page.app()
AttributeError: 'function' object has no attribute 'app'

2022-02-15 17:14:05.975 Traceback (most recent call last):
  File "/dados01/workspace/ufmg_2021_f01/ufmg.cmikaela/.local/lib/python3.6/site-packages/streamlit/script_runner.py", line 379, in _run_script
    exec(code, module.__dict__)
  File "/dados01/workspace/ufmg_2021_f01/ufmg.cmikaela/dev/config-coleta-generator/app.py", line 148, in <module>
    page.app()
AttributeError: 'function' object has no attribute 'app'

2022-02-15 17:14:07.841 Traceback (most recent call last):
  File "/dados01/workspace/ufmg_2021_f01/ufmg.cmikaela/.local/lib/python3.6/site-packages/streamlit/script_runner.py", line 379, in _run_script
    exec(code, module.__dict__)
  File "/dados01/workspace/ufmg_2021_f01/ufmg.cmikaela/dev/config-coleta-generator/app.py", line 148, in <module>
    page.app()
AttributeError: 'function' object has no attribute 'app'

2022-02-15 17:16:35.727 Traceback (most recent call last):
  File "/dados01/workspace/ufmg_2021_f01/ufmg.cmikaela/.local/lib/python3.6/site-packages/streamlit/script_runner.py", line 379, in _run_script
    exec(code, module.__dict__)
  File "/dados01/workspace/ufmg_2021_f01/ufmg.cmikaela/dev/config-coleta-generator/app.py", line 153, in <module>
    page.app1()
AttributeError: 'function' object has no attribute 'app1'

2022-02-15 17:18:30.966 Traceback (most recent call last):
  File "/dados01/workspace/ufmg_2021_f01/ufmg.cmikaela/.local/lib/python3.6/site-packages/streamlit/script_runner.py", line 379, in _run_script
    exec(code, module.__dict__)
  File "/dados01/workspace/ufmg_2021_f01/ufmg.cmikaela/dev/config-coleta-generator/app.py", line 147, in <module>
    selection = st.sidebar.radio(list(PAGES.keys()))
TypeError: radio() missing 1 required positional argument: 'options'

2022-02-15 17:26:20.556 Traceback (most recent call last):
  File "/dados01/workspace/ufmg_2021_f01/ufmg.cmikaela/.local/lib/python3.6/site-packages/streamlit/script_runner.py", line 379, in _run_script
    exec(code, module.__dict__)
  File "/dados01/workspace/ufmg_2021_f01/ufmg.cmikaela/dev/config-coleta-generator/app.py", line 161, in <module>
    page()
  File "/dados01/workspace/ufmg_2021_f01/ufmg.cmikaela/dev/config-coleta-generator/app.py", line 142, in app2
    with open(file, 'r') as f:
IsADirectoryError: [Errno 21] Is a directory: 'temp'

2022-02-15 17:26:51.473 Traceback (most recent call last):
  File "/dados01/workspace/ufmg_2021_f01/ufmg.cmikaela/.local/lib/python3.6/site-packages/streamlit/script_runner.py", line 379, in _run_script
    exec(code, module.__dict__)
  File "/dados01/workspace/ufmg_2021_f01/ufmg.cmikaela/dev/config-coleta-generator/app.py", line 161, in <module>
    page()
  File "/dados01/workspace/ufmg_2021_f01/ufmg.cmikaela/dev/config-coleta-generator/app.py", line 142, in app2
    with open(file, 'r') as f:
IsADirectoryError: [Errno 21] Is a directory: 'temp/'

2022-02-15 17:27:21.578 Traceback (most recent call last):
  File "/dados01/workspace/ufmg_2021_f01/ufmg.cmikaela/.local/lib/python3.6/site-packages/streamlit/script_runner.py", line 379, in _run_script
    exec(code, module.__dict__)
  File "/dados01/workspace/ufmg_2021_f01/ufmg.cmikaela/dev/config-coleta-generator/app.py", line 161, in <module>
    page()
  File "/dados01/workspace/ufmg_2021_f01/ufmg.cmikaela/dev/config-coleta-generator/app.py", line 142, in app2
    with open(f'temp/{file}', 'r') as f:
FileNotFoundError: [Errno 2] No such file or directory: 'temp/temp/'

2022-02-15 17:27:38.160 Traceback (most recent call last):
  File "/dados01/workspace/ufmg_2021_f01/ufmg.cmikaela/.local/lib/python3.6/site-packages/streamlit/script_runner.py", line 379, in _run_script
    exec(code, module.__dict__)
  File "/dados01/workspace/ufmg_2021_f01/ufmg.cmikaela/dev/config-coleta-generator/app.py", line 161, in <module>
    page()
  File "/dados01/workspace/ufmg_2021_f01/ufmg.cmikaela/dev/config-coleta-generator/app.py", line 142, in app2
    with open(f'temp/{file}', 'r') as f:
FileNotFoundError: [Errno 2] No such file or directory: 'temp/temp'

2022-02-15 17:27:51.855 Traceback (most recent call last):
  File "/dados01/workspace/ufmg_2021_f01/ufmg.cmikaela/.local/lib/python3.6/site-packages/streamlit/script_runner.py", line 379, in _run_script
    exec(code, module.__dict__)
  File "/dados01/workspace/ufmg_2021_f01/ufmg.cmikaela/dev/config-coleta-generator/app.py", line 161, in <module>
    page()
  File "/dados01/workspace/ufmg_2021_f01/ufmg.cmikaela/dev/config-coleta-generator/app.py", line 142, in app2
    with open(f'temp/{file}', 'r') as f:
FileNotFoundError: [Errno 2] No such file or directory: 'temp/temp/config_Engenheiro Navarro.json'

2022-02-15 17:30:32.421 Traceback (most recent call last):
  File "/dados01/workspace/ufmg_2021_f01/ufmg.cmikaela/.local/lib/python3.6/site-packages/streamlit/script_runner.py", line 379, in _run_script
    exec(code, module.__dict__)
  File "/dados01/workspace/ufmg_2021_f01/ufmg.cmikaela/dev/config-coleta-generator/app.py", line 168, in <module>
    page()
  File "/dados01/workspace/ufmg_2021_f01/ufmg.cmikaela/dev/config-coleta-generator/app.py", line 152, in app2
    st.write(config)
UnboundLocalError: local variable 'config' referenced before assignment

2022-02-15 21:13:33.003 Traceback (most recent call last):
  File "/dados01/workspace/ufmg_2021_f01/ufmg.cmikaela/.local/lib/python3.6/site-packages/streamlit/script_runner.py", line 379, in _run_script
    exec(code, module.__dict__)
  File "/dados01/workspace/ufmg_2021_f01/ufmg.cmikaela/dev/config-coleta-generator/app.py", line 173, in <module>
    page()
  File "/dados01/workspace/ufmg_2021_f01/ufmg.cmikaela/dev/config-coleta-generator/app.py", line 155, in app2
    create_and_run_coletor(config)
  File "/dados01/workspace/ufmg_2021_f01/ufmg.cmikaela/dev/config-coleta-generator/app.py", line 68, in create_and_run_coletor
    id_crawler = configuracao_do_coletor_criado['id']
KeyError: 'id'

2022-02-15 21:13:58.355 Traceback (most recent call last):
  File "/dados01/workspace/ufmg_2021_f01/ufmg.cmikaela/.local/lib/python3.6/site-packages/streamlit/script_runner.py", line 379, in _run_script
    exec(code, module.__dict__)
  File "/dados01/workspace/ufmg_2021_f01/ufmg.cmikaela/dev/config-coleta-generator/app.py", line 173, in <module>
    page()
  File "/dados01/workspace/ufmg_2021_f01/ufmg.cmikaela/dev/config-coleta-generator/app.py", line 155, in app2
    create_and_run_coletor(config)
  File "/dados01/workspace/ufmg_2021_f01/ufmg.cmikaela/dev/config-coleta-generator/app.py", line 68, in create_and_run_coletor
    id_crawler = configuracao_do_coletor_criado['id']
KeyError: 'id'

2022-02-15 21:15:58.020 Traceback (most recent call last):
  File "/dados01/workspace/ufmg_2021_f01/ufmg.cmikaela/.local/lib/python3.6/site-packages/streamlit/script_runner.py", line 379, in _run_script
    exec(code, module.__dict__)
  File "/dados01/workspace/ufmg_2021_f01/ufmg.cmikaela/dev/config-coleta-generator/app.py", line 173, in <module>
    page()
  File "/dados01/workspace/ufmg_2021_f01/ufmg.cmikaela/dev/config-coleta-generator/app.py", line 155, in app2
    create_and_run_coletor(config)
  File "/dados01/workspace/ufmg_2021_f01/ufmg.cmikaela/dev/config-coleta-generator/app.py", line 68, in create_and_run_coletor
    id_crawler = configuracao_do_coletor_criado['id']
KeyError: 'id'

2022-02-16 19:57:14.182 Traceback (most recent call last):
  File "/dados01/workspace/ufmg_2021_f01/ufmg.cmikaela/.local/lib/python3.6/site-packages/streamlit/script_runner.py", line 379, in _run_script
    exec(code, module.__dict__)
  File "/dados01/workspace/ufmg_2021_f01/ufmg.cmikaela/dev/config-coleta-generator/app.py", line 173, in <module>
    page()
  File "/dados01/workspace/ufmg_2021_f01/ufmg.cmikaela/dev/config-coleta-generator/app.py", line 155, in app2
    create_and_run_coletor(config)
  File "/dados01/workspace/ufmg_2021_f01/ufmg.cmikaela/dev/config-coleta-generator/app.py", line 68, in create_and_run_coletor
    id_crawler = configuracao_do_coletor_criado['id']
KeyError: 'id'

2022-02-17 14:06:13.834 Traceback (most recent call last):
  File "/usr/local/lib/python3.6/site-packages/urllib3/connectionpool.py", line 672, in urlopen
    chunked=chunked,
  File "/usr/local/lib/python3.6/site-packages/urllib3/connectionpool.py", line 421, in _make_request
    six.raise_from(e, None)
  File "<string>", line 3, in raise_from
  File "/usr/local/lib/python3.6/site-packages/urllib3/connectionpool.py", line 416, in _make_request
    httplib_response = conn.getresponse()
  File "/usr/lib64/python3.6/http/client.py", line 1346, in getresponse
    response.begin()
  File "/usr/lib64/python3.6/http/client.py", line 307, in begin
    version, status, reason = self._read_status()
  File "/usr/lib64/python3.6/http/client.py", line 276, in _read_status
    raise RemoteDisconnected("Remote end closed connection without"
http.client.RemoteDisconnected: Remote end closed connection without response

During handling of the above exception, another exception occurred:

Traceback (most recent call last):
  File "/usr/local/lib/python3.6/site-packages/requests/adapters.py", line 449, in send
    timeout=timeout
  File "/usr/local/lib/python3.6/site-packages/urllib3/connectionpool.py", line 720, in urlopen
    method, url, error=e, _pool=self, _stacktrace=sys.exc_info()[2]
  File "/usr/local/lib/python3.6/site-packages/urllib3/util/retry.py", line 400, in increment
    raise six.reraise(type(error), error, _stacktrace)
  File "/usr/local/lib/python3.6/site-packages/urllib3/packages/six.py", line 734, in reraise
    raise value.with_traceback(tb)
  File "/usr/local/lib/python3.6/site-packages/urllib3/connectionpool.py", line 672, in urlopen
    chunked=chunked,
  File "/usr/local/lib/python3.6/site-packages/urllib3/connectionpool.py", line 421, in _make_request
    six.raise_from(e, None)
  File "<string>", line 3, in raise_from
  File "/usr/local/lib/python3.6/site-packages/urllib3/connectionpool.py", line 416, in _make_request
    httplib_response = conn.getresponse()
  File "/usr/lib64/python3.6/http/client.py", line 1346, in getresponse
    response.begin()
  File "/usr/lib64/python3.6/http/client.py", line 307, in begin
    version, status, reason = self._read_status()
  File "/usr/lib64/python3.6/http/client.py", line 276, in _read_status
    raise RemoteDisconnected("Remote end closed connection without"
urllib3.exceptions.ProtocolError: ('Connection aborted.', RemoteDisconnected('Remote end closed connection without response',))

During handling of the above exception, another exception occurred:

Traceback (most recent call last):
  File "/dados01/workspace/ufmg_2021_f01/ufmg.cmikaela/.local/lib/python3.6/site-packages/streamlit/script_runner.py", line 379, in _run_script
    exec(code, module.__dict__)
  File "/dados01/workspace/ufmg_2021_f01/ufmg.cmikaela/dev/config-coleta-generator/app.py", line 177, in <module>
    page()
  File "/dados01/workspace/ufmg_2021_f01/ufmg.cmikaela/dev/config-coleta-generator/app.py", line 159, in app2
    create_and_run_coletor(config)
  File "/dados01/workspace/ufmg_2021_f01/ufmg.cmikaela/dev/config-coleta-generator/app.py", line 66, in create_and_run_coletor
    r_creator = requests.post(API_ADDRESS, data=config)
  File "/usr/local/lib/python3.6/site-packages/requests/api.py", line 119, in post
    return request('post', url, data=data, json=json, **kwargs)
  File "/usr/local/lib/python3.6/site-packages/requests/api.py", line 61, in request
    return session.request(method=method, url=url, **kwargs)
  File "/usr/local/lib/python3.6/site-packages/requests/sessions.py", line 530, in request
    resp = self.send(prep, **send_kwargs)
  File "/usr/local/lib/python3.6/site-packages/requests/sessions.py", line 643, in send
    r = adapter.send(request, **kwargs)
  File "/usr/local/lib/python3.6/site-packages/requests/adapters.py", line 498, in send
    raise ConnectionError(err, request=request)
requests.exceptions.ConnectionError: ('Connection aborted.', RemoteDisconnected('Remote end closed connection without response',))

2022-02-17 14:33:51.901 Traceback (most recent call last):
  File "/usr/local/lib/python3.6/site-packages/urllib3/connectionpool.py", line 672, in urlopen
    chunked=chunked,
  File "/usr/local/lib/python3.6/site-packages/urllib3/connectionpool.py", line 421, in _make_request
    six.raise_from(e, None)
  File "<string>", line 3, in raise_from
  File "/usr/local/lib/python3.6/site-packages/urllib3/connectionpool.py", line 416, in _make_request
    httplib_response = conn.getresponse()
  File "/usr/lib64/python3.6/http/client.py", line 1346, in getresponse
    response.begin()
  File "/usr/lib64/python3.6/http/client.py", line 307, in begin
    version, status, reason = self._read_status()
  File "/usr/lib64/python3.6/http/client.py", line 276, in _read_status
    raise RemoteDisconnected("Remote end closed connection without"
http.client.RemoteDisconnected: Remote end closed connection without response

During handling of the above exception, another exception occurred:

Traceback (most recent call last):
  File "/usr/local/lib/python3.6/site-packages/requests/adapters.py", line 449, in send
    timeout=timeout
  File "/usr/local/lib/python3.6/site-packages/urllib3/connectionpool.py", line 720, in urlopen
    method, url, error=e, _pool=self, _stacktrace=sys.exc_info()[2]
  File "/usr/local/lib/python3.6/site-packages/urllib3/util/retry.py", line 400, in increment
    raise six.reraise(type(error), error, _stacktrace)
  File "/usr/local/lib/python3.6/site-packages/urllib3/packages/six.py", line 734, in reraise
    raise value.with_traceback(tb)
  File "/usr/local/lib/python3.6/site-packages/urllib3/connectionpool.py", line 672, in urlopen
    chunked=chunked,
  File "/usr/local/lib/python3.6/site-packages/urllib3/connectionpool.py", line 421, in _make_request
    six.raise_from(e, None)
  File "<string>", line 3, in raise_from
  File "/usr/local/lib/python3.6/site-packages/urllib3/connectionpool.py", line 416, in _make_request
    httplib_response = conn.getresponse()
  File "/usr/lib64/python3.6/http/client.py", line 1346, in getresponse
    response.begin()
  File "/usr/lib64/python3.6/http/client.py", line 307, in begin
    version, status, reason = self._read_status()
  File "/usr/lib64/python3.6/http/client.py", line 276, in _read_status
    raise RemoteDisconnected("Remote end closed connection without"
urllib3.exceptions.ProtocolError: ('Connection aborted.', RemoteDisconnected('Remote end closed connection without response',))

During handling of the above exception, another exception occurred:

Traceback (most recent call last):
  File "/dados01/workspace/ufmg_2021_f01/ufmg.cmikaela/.local/lib/python3.6/site-packages/streamlit/script_runner.py", line 379, in _run_script
    exec(code, module.__dict__)
  File "/dados01/workspace/ufmg_2021_f01/ufmg.cmikaela/dev/config-coleta-generator/app.py", line 175, in <module>
    page()
  File "/dados01/workspace/ufmg_2021_f01/ufmg.cmikaela/dev/config-coleta-generator/app.py", line 137, in app1
    create_and_run_coletor(i)
  File "/dados01/workspace/ufmg_2021_f01/ufmg.cmikaela/dev/config-coleta-generator/app.py", line 66, in create_and_run_coletor
    r_creator = requests.post(API_ADDRESS, data=config)
  File "/usr/local/lib/python3.6/site-packages/requests/api.py", line 119, in post
    return request('post', url, data=data, json=json, **kwargs)
  File "/usr/local/lib/python3.6/site-packages/requests/api.py", line 61, in request
    return session.request(method=method, url=url, **kwargs)
  File "/usr/local/lib/python3.6/site-packages/requests/sessions.py", line 530, in request
    resp = self.send(prep, **send_kwargs)
  File "/usr/local/lib/python3.6/site-packages/requests/sessions.py", line 643, in send
    r = adapter.send(request, **kwargs)
  File "/usr/local/lib/python3.6/site-packages/requests/adapters.py", line 498, in send
    raise ConnectionError(err, request=request)
requests.exceptions.ConnectionError: ('Connection aborted.', RemoteDisconnected('Remote end closed connection without response',))

2022-02-17 15:07:47.120 Traceback (most recent call last):
  File "/usr/local/lib/python3.6/site-packages/urllib3/connectionpool.py", line 672, in urlopen
    chunked=chunked,
  File "/usr/local/lib/python3.6/site-packages/urllib3/connectionpool.py", line 421, in _make_request
    six.raise_from(e, None)
  File "<string>", line 3, in raise_from
  File "/usr/local/lib/python3.6/site-packages/urllib3/connectionpool.py", line 416, in _make_request
    httplib_response = conn.getresponse()
  File "/usr/lib64/python3.6/http/client.py", line 1346, in getresponse
    response.begin()
  File "/usr/lib64/python3.6/http/client.py", line 307, in begin
    version, status, reason = self._read_status()
  File "/usr/lib64/python3.6/http/client.py", line 276, in _read_status
    raise RemoteDisconnected("Remote end closed connection without"
http.client.RemoteDisconnected: Remote end closed connection without response

During handling of the above exception, another exception occurred:

Traceback (most recent call last):
  File "/usr/local/lib/python3.6/site-packages/requests/adapters.py", line 449, in send
    timeout=timeout
  File "/usr/local/lib/python3.6/site-packages/urllib3/connectionpool.py", line 720, in urlopen
    method, url, error=e, _pool=self, _stacktrace=sys.exc_info()[2]
  File "/usr/local/lib/python3.6/site-packages/urllib3/util/retry.py", line 400, in increment
    raise six.reraise(type(error), error, _stacktrace)
  File "/usr/local/lib/python3.6/site-packages/urllib3/packages/six.py", line 734, in reraise
    raise value.with_traceback(tb)
  File "/usr/local/lib/python3.6/site-packages/urllib3/connectionpool.py", line 672, in urlopen
    chunked=chunked,
  File "/usr/local/lib/python3.6/site-packages/urllib3/connectionpool.py", line 421, in _make_request
    six.raise_from(e, None)
  File "<string>", line 3, in raise_from
  File "/usr/local/lib/python3.6/site-packages/urllib3/connectionpool.py", line 416, in _make_request
    httplib_response = conn.getresponse()
  File "/usr/lib64/python3.6/http/client.py", line 1346, in getresponse
    response.begin()
  File "/usr/lib64/python3.6/http/client.py", line 307, in begin
    version, status, reason = self._read_status()
  File "/usr/lib64/python3.6/http/client.py", line 276, in _read_status
    raise RemoteDisconnected("Remote end closed connection without"
urllib3.exceptions.ProtocolError: ('Connection aborted.', RemoteDisconnected('Remote end closed connection without response',))

During handling of the above exception, another exception occurred:

Traceback (most recent call last):
  File "/dados01/workspace/ufmg_2021_f01/ufmg.cmikaela/.local/lib/python3.6/site-packages/streamlit/script_runner.py", line 379, in _run_script
    exec(code, module.__dict__)
  File "/dados01/workspace/ufmg_2021_f01/ufmg.cmikaela/dev/config-coleta-generator/app.py", line 175, in <module>
    page()
  File "/dados01/workspace/ufmg_2021_f01/ufmg.cmikaela/dev/config-coleta-generator/app.py", line 137, in app1
    create_and_run_coletor(i)
  File "/dados01/workspace/ufmg_2021_f01/ufmg.cmikaela/dev/config-coleta-generator/app.py", line 66, in create_and_run_coletor
    r_creator = requests.post(API_ADDRESS, data=config)
  File "/usr/local/lib/python3.6/site-packages/requests/api.py", line 119, in post
    return request('post', url, data=data, json=json, **kwargs)
  File "/usr/local/lib/python3.6/site-packages/requests/api.py", line 61, in request
    return session.request(method=method, url=url, **kwargs)
  File "/usr/local/lib/python3.6/site-packages/requests/sessions.py", line 530, in request
    resp = self.send(prep, **send_kwargs)
  File "/usr/local/lib/python3.6/site-packages/requests/sessions.py", line 643, in send
    r = adapter.send(request, **kwargs)
  File "/usr/local/lib/python3.6/site-packages/requests/adapters.py", line 498, in send
    raise ConnectionError(err, request=request)
requests.exceptions.ConnectionError: ('Connection aborted.', RemoteDisconnected('Remote end closed connection without response',))


  You can now view your Streamlit app in your browser.

  Network URL: http://10.21.0.126:8040
  External URL: http://177.190.215.14:8040

